Workbook

Sheet Donnees
A1: Vent | B1: Est | C1: Sud | D1: Ouest | E1: Nord | F1: ="Partie " & (ROW()-1)/4+1 -> Partie 1
A2: Nom joueur | B2: Isabelle | C2: Marc | D2: Guilhem | E2: Christophe | F2: 45903.59
A3: Mini-points | B3: 59 | C3: -58 | D3: 146 | E3: -147
A4: Points de table | B4: =4-_xlfn.RANK.AVG(B3,$B3:$E3) -> 2 | C4: =4-_xlfn.RANK.AVG(C3,$B3:$E3) -> 1 | D4: =4-_xlfn.RANK.AVG(D3,$B3:$E3) -> 3 | E4: =4-_xlfn.RANK.AVG(E3,$B3:$E3) -> 0
A5: Vent | B5: Est | C5: Sud | D5: Ouest | E5: Nord | F5: ="Partie " & (ROW()-1)/4+1 -> Partie 2
A6: Nom joueur | B6: Christophe | C6: Marc | D6: Guilhem | E6: Isabelle | F6: 45903.68
A7: Mini-points | B7: 131 | C7: -27 | D7: -17 | E7: -87
A8: Points de table | B8: =4-_xlfn.RANK.AVG(B7,$B7:$E7) -> 3 | C8: =4-_xlfn.RANK.AVG(C7,$B7:$E7) -> 1 | D8: =4-_xlfn.RANK.AVG(D7,$B7:$E7) -> 2 | E8: =4-_xlfn.RANK.AVG(E7,$B7:$E7) -> 0
A9: Vent | B9: Est | C9: Sud | D9: Ouest | E9: Nord | F9: ="Partie " & (ROW()-1)/4+1 -> Partie 3
A10: Nom joueur | B10: Raphael | C10: Marc | D10: Guilhem | E10: Christophe | F10: 45904.608
A11: Mini-points | B11: -45 | C11: -200 | D11: 63 | E11: 182
A12: Points de table | B12: =4-_xlfn.RANK.AVG(B11,$B11:$E11) -> 1 | C12: =4-_xlfn.RANK.AVG(C11,$B11:$E11) -> 0 | D12: =4-_xlfn.RANK.AVG(D11,$B11:$E11) -> 2 | E12: =4-_xlfn.RANK.AVG(E11,$B11:$E11) -> 3
A13: Vent | B13: Est | C13: Sud | D13: Ouest | E13: Nord | F13: ="Partie " & (ROW()-1)/4+1 -> Partie 4
A14: Nom joueur | B14: Christophe | C14: Marc | D14: Raphael | E14: Guilhem | F14: 45904.693
A15: Mini-points | B15: -67 | C15: 35 | D15: -99 | E15: 131
A16: Points de table | B16: =4-_xlfn.RANK.AVG(B15,$B15:$E15) -> 1 | C16: =4-_xlfn.RANK.AVG(C15,$B15:$E15) -> 2 | D16: =4-_xlfn.RANK.AVG(D15,$B15:$E15) -> 0 | E16: =4-_xlfn.RANK.AVG(E15,$B15:$E15) -> 3
A17: Vent | B17: Est | C17: Sud | D17: Ouest | E17: Nord | F17: ="Partie " & (ROW()-1)/4+1 -> Partie 5
A18: Nom joueur | B18: Delphine | C18: Isabelle | D18: Mathieu | E18: Ghislaine | F18: 45906.588
A19: Mini-points | B19: 30 | C19: 66 | D19: -84 | E19: -12
A20: Points de table | B20: =4-_xlfn.RANK.AVG(B19,$B19:$E19) -> 2 | C20: =4-_xlfn.RANK.AVG(C19,$B19:$E19) -> 3 | D20: =4-_xlfn.RANK.AVG(D19,$B19:$E19) -> 0 | E20: =4-_xlfn.RANK.AVG(E19,$B19:$E19) -> 1
A21: Vent | B21: Est | C21: Sud | D21: Ouest | E21: Nord | F21: ="Partie " & (ROW()-1)/4+1 -> Partie 6
A22: Nom joueur | B22: Francoise | C22: Marc | D22: Beatrice | E22: Sebastien | F22: 45906.589
A23: Mini-points | B23: -103 | C23: 15 | D23: -62 | E23: 150
A24: Points de table | B24: =4-_xlfn.RANK.AVG(B23,$B23:$E23) -> 0 | C24: =4-_xlfn.RANK.AVG(C23,$B23:$E23) -> 2 | D24: =4-_xlfn.RANK.AVG(D23,$B23:$E23) -> 1 | E24: =4-_xlfn.RANK.AVG(E23,$B23:$E23) -> 3
A25: Vent | B25: Est | C25: Sud | D25: Ouest | E25: Nord | F25: ="Partie " & (ROW()-1)/4+1 -> Partie 7
A26: Nom joueur | B26: Marc | C26: Raphael | D26: Guilhem | E26: Sebastien | F26: 45906.697
A27: Mini-points | B27: -235 | C27: -79 | D27: 275 | E27: 39
A28: Points de table | B28: =4-_xlfn.RANK.AVG(B27,$B27:$E27) -> 0 | C28: =4-_xlfn.RANK.AVG(C27,$B27:$E27) -> 1 | D28: =4-_xlfn.RANK.AVG(D27,$B27:$E27) -> 3 | E28: =4-_xlfn.RANK.AVG(E27,$B27:$E27) -> 2
A29: Vent | B29: Est | C29: Sud | D29: Ouest | E29: Nord | F29: ="Partie " & (ROW()-1)/4+1 -> Partie 8
A30: Nom joueur | B30: Mathieu | C30: Isabelle | D30: Francoise | E30: Christophe | F30: 45906.704
A31: Mini-points | B31: -11 | C31: 49 | D31: -55 | E31: 17
A32: Points de table | B32: =4-_xlfn.RANK.AVG(B31,$B31:$E31) -> 1 | C32: =4-_xlfn.RANK.AVG(C31,$B31:$E31) -> 3 | D32: =4-_xlfn.RANK.AVG(D31,$B31:$E31) -> 0 | E32: =4-_xlfn.RANK.AVG(E31,$B31:$E31) -> 2
A33: Vent | B33: Est | C33: Sud | D33: Ouest | E33: Nord | F33: ="Partie " & (ROW()-1)/4+1 -> Partie 9
A34: Nom joueur | B34: Binome | C34: Marie | D34: Christophe | E34: Valerie D | F34: 45906.856
A35: Mini-points | B35: 130 | C35: -150 | D35: -37 | E35: 57
A36: Points de table | B36: =4-_xlfn.RANK.AVG(B35,$B35:$E35) -> 3 | C36: =4-_xlfn.RANK.AVG(C35,$B35:$E35) -> 0 | D36: =4-_xlfn.RANK.AVG(D35,$B35:$E35) -> 1 | E36: =4-_xlfn.RANK.AVG(E35,$B35:$E35) -> 2
A37: Vent | B37: Est | C37: Sud | D37: Ouest | E37: Nord | F37: ="Partie " & (ROW()-1)/4+1 -> Partie 10
A38: Nom joueur | B38: Jean-Michel | C38: Richard | D38: Sebastien | E38: Laurence | F38: 45913.594
A39: Mini-points | B39: -98 | C39: 161 | D39: -164 | E39: 101
A40: Points de table | B40: =4-_xlfn.RANK.AVG(B39,$B39:$E39) -> 1 | C40: =4-_xlfn.RANK.AVG(C39,$B39:$E39) -> 3 | D40: =4-_xlfn.RANK.AVG(D39,$B39:$E39) -> 0 | E40: =4-_xlfn.RANK.AVG(E39,$B39:$E39) -> 2
...

Sheet Check
A1: Vent | B1: Est | C1: Sud | D1: Ouest | E1: Nord | F1: =Donnees!F1 -> Partie 1 | H1: Signature : | I1: =_xlfn.TEXTJOIN(";",TRUE,B2:E3) -> Isabelle;Marc;Guilhem;Christophe;59;-58;146;-147
A2: Nom joueur | B2: Isabelle | C2: Marc | D2: Guilhem | E2: Christophe | F2: 45903.59 | H2: Check identique : | I2: {=IF(AND(Donnees!B1:F4=Check!B1:F4),"Identique","PAS IDENTIQUE")} -> Identique | J2: Check double noms : | K2: {=IF(MAX(COUNTIF(B2:E2,B2:E2)) > 1, "JOUEUR EN DOUBLE", "Pas de doublons")} -> Pas de doublons
A3: Mini-points | B3: 59 | C3: -58 | D3: 146 | E3: -147 | H3: Check doublons partie : | I3: =IF(COUNTIF(I$1:I2,I1)>1,"DOUBLON LIGNE " & MATCH(I1,I$1:I2,0),"Pas de doublons") -> Pas de doublons | J3: Check noms existants : | K3: {=IF(SUM(--(NOT(ISNUMBER(MATCH(B2:E2,'EMA points'!A:A,0))))) > 0, "NOM INEXISTANT", "Noms ok")} -> Noms ok
A4: Points de table | B4: =Donnees!B4 -> 2 | C4: =Donnees!C4 -> 1 | D4: =Donnees!D4 -> 3 | E4: =Donnees!E4 -> 0 | H4: Check score : | I4: =IF(SUM(B3:E3)=0, "Score ok", "SOMME NON NULLE") -> Score ok
A5: Vent | B5: Est | C5: Sud | D5: Ouest | E5: Nord | F5: =Donnees!F5 -> Partie 2 | H5: Signature : | I5: =_xlfn.TEXTJOIN(";",TRUE,B6:E7) -> Christophe;Marc;Guilhem;Isabelle;131;-27;-17;-87
A6: Nom joueur | B6: Christophe | C6: Marc | D6: Guilhem | E6: Isabelle | F6: 45903.68 | H6: Check identique : | I6: {=IF(AND(Donnees!B5:F8=Check!B5:F8),"Identique","PAS IDENTIQUE")} -> Identique | J6: Check double noms : | K6: {=IF(MAX(COUNTIF(B6:E6,B6:E6)) > 1, "JOUEUR EN DOUBLE", "Pas de doublons")} -> Pas de doublons
A7: Mini-points | B7: 131 | C7: -27 | D7: -17 | E7: -87 | H7: Check doublons partie : | I7: =IF(COUNTIF(I$1:I6,I5)>1,"DOUBLON LIGNE " & MATCH(I5,I$1:I6,0),"Pas de doublons") -> Pas de doublons | J7: Check noms existants : | K7: {=IF(SUM(--(NOT(ISNUMBER(MATCH(B6:E6,'EMA points'!A:A,0))))) > 0, "NOM INEXISTANT", "Noms ok")} -> Noms ok
A8: Points de table | B8: =Donnees!B8 -> 3 | C8: =Donnees!C8 -> 1 | D8: =Donnees!D8 -> 2 | E8: =Donnees!E8 -> 0 | H8: Check score : | I8: =IF(SUM(B7:E7)=0, "Score ok", "SOMME NON NULLE") -> Score ok
A9: Vent | B9: Est | C9: Sud | D9: Ouest | E9: Nord | F9: =Donnees!F9 -> Partie 3 | H9: Signature : | I9: =_xlfn.TEXTJOIN(";",TRUE,B10:E11) -> Raphael;Marc;Guilhem;Christophe;-45;-200;63;182
A10: Nom joueur | B10: Raphael | C10: Marc | D10: Guilhem | E10: Christophe | F10: 45904.608 | H10: Check identique : | I10: {=IF(AND(Donnees!B9:F12=Check!B9:F12),"Identique","PAS IDENTIQUE")} -> Identique | J10: Check double noms : | K10: {=IF(MAX(COUNTIF(B10:E10,B10:E10)) > 1, "JOUEUR EN DOUBLE", "Pas de doublons")} -> Pas de doublons
A11: Mini-points | B11: -45 | C11: -200 | D11: 63 | E11: 182 | H11: Check doublons partie : | I11: =IF(COUNTIF(I$1:I10,I9)>1,"DOUBLON LIGNE " & MATCH(I9,I$1:I10,0),"Pas de doublons") -> Pas de doublons | J11: Check noms existants : | K11: {=IF(SUM(--(NOT(ISNUMBER(MATCH(B10:E10,'EMA points'!A:A,0))))) > 0, "NOM INEXISTANT", "Noms ok")} -> Noms ok
A12: Points de table | B12: =Donnees!B12 -> 1 | C12: =Donnees!C12 -> 0 | D12: =Donnees!D12 -> 2 | E12: =Donnees!E12 -> 3 | H12: Check score : | I12: =IF(SUM(B11:E11)=0, "Score ok", "SOMME NON NULLE") -> Score ok
A13: Vent | B13: Est | C13: Sud | D13: Ouest | E13: Nord | F13: =Donnees!F13 -> Partie 4 | H13: Signature : | I13: =_xlfn.TEXTJOIN(";",TRUE,B14:E15) -> Christophe;Marc;Raphael;Guilhem;-67;35;-99;131
A14: Nom joueur | B14: Christophe | C14: Marc | D14: Raphael | E14: Guilhem | F14: 45904.693 | H14: Check identique : | I14: {=IF(AND(Donnees!B13:F16=Check!B13:F16),"Identique","PAS IDENTIQUE")} -> Identique | J14: Check double noms : | K14: {=IF(MAX(COUNTIF(B14:E14,B14:E14)) > 1, "JOUEUR EN DOUBLE", "Pas de doublons")} -> Pas de doublons
A15: Mini-points | B15: -67 | C15: 35 | D15: -99 | E15: 131 | H15: Check doublons partie : | I15: =IF(COUNTIF(I$1:I14,I13)>1,"DOUBLON LIGNE " & MATCH(I13,I$1:I14,0),"Pas de doublons") -> Pas de doublons | J15: Check noms existants : | K15: {=IF(SUM(--(NOT(ISNUMBER(MATCH(B14:E14,'EMA points'!A:A,0))))) > 0, "NOM INEXISTANT", "Noms ok")} -> Noms ok
A16: Points de table | B16: =Donnees!B16 -> 1 | C16: =Donnees!C16 -> 2 | D16: =Donnees!D16 -> 0 | E16: =Donnees!E16 -> 3 | H16: Check score : | I16: =IF(SUM(B15:E15)=0, "Score ok", "SOMME NON NULLE") -> Score ok
A17: Vent | B17: Est | C17: Sud | D17: Ouest | E17: Nord | F17: =Donnees!F17 -> Partie 5 | H17: Signature : | I17: =_xlfn.TEXTJOIN(";",TRUE,B18:E19) -> Delphine;Isabelle;Mathieu;Ghislaine;30;66;-84;-12
A18: Nom joueur | B18: Delphine | C18: Isabelle | D18: Mathieu | E18: Ghislaine | F18: 45906.588 | H18: Check identique : | I18: {=IF(AND(Donnees!B17:F20=Check!B17:F20),"Identique","PAS IDENTIQUE")} -> Identique | J18: Check double noms : | K18: {=IF(MAX(COUNTIF(B18:E18,B18:E18)) > 1, "JOUEUR EN DOUBLE", "Pas de doublons")} -> Pas de doublons
A19: Mini-points | B19: 30 | C19: 66 | D19: -84 | E19: -12 | H19: Check doublons partie : | I19: =IF(COUNTIF(I$1:I18,I17)>1,"DOUBLON LIGNE " & MATCH(I17,I$1:I18,0),"Pas de doublons") -> Pas de doublons | J19: Check noms existants : | K19: {=IF(SUM(--(NOT(ISNUMBER(MATCH(B18:E18,'EMA points'!A:A,0))))) > 0, "NOM INEXISTANT", "Noms ok")} -> Noms ok
A20: Points de table | B20: =Donnees!B20 -> 2 | C20: =Donnees!C20 -> 3 | D20: =Donnees!D20 -> 0 | E20: =Donnees!E20 -> 1 | H20: Check score : | I20: =IF(SUM(B19:E19)=0, "Score ok", "SOMME NON NULLE") -> Score ok
A21: Vent | B21: Est | C21: Sud | D21: Ouest | E21: Nord | F21: =Donnees!F21 -> Partie 6 | H21: Signature : | I21: =_xlfn.TEXTJOIN(";",TRUE,B22:E23) -> Francoise;Marc;Beatrice;Sebastien;-103;15;-62;150
A22: Nom joueur | B22: Francoise | C22: Marc | D22: Beatrice | E22: Sebastien | F22: 45906.589 | H22: Check identique : | I22: {=IF(AND(Donnees!B21:F24=Check!B21:F24),"Identique","PAS IDENTIQUE")} -> Identique | J22: Check double noms : | K22: {=IF(MAX(COUNTIF(B22:E22,B22:E22)) > 1, "JOUEUR EN DOUBLE", "Pas de doublons")} -> Pas de doublons
A23: Mini-points | B23: -103 | C23: 15 | D23: -62 | E23: 150 | H23: Check doublons partie : | I23: =IF(COUNTIF(I$1:I22,I21)>1,"DOUBLON LIGNE " & MATCH(I21,I$1:I22,0),"Pas de doublons") -> Pas de doublons | J23: Check noms existants : | K23: {=IF(SUM(--(NOT(ISNUMBER(MATCH(B22:E22,'EMA points'!A:A,0))))) > 0, "NOM INEXISTANT", "Noms ok")} -> Noms ok
A24: Points de table | B24: =Donnees!B24 -> 0 | C24: =Donnees!C24 -> 2 | D24: =Donnees!D24 -> 1 | E24: =Donnees!E24 -> 3 | H24: Check score : | I24: =IF(SUM(B23:E23)=0, "Score ok", "SOMME NON NULLE") -> Score ok
A25: Vent | B25: Est | C25: Sud | D25: Ouest | E25: Nord | F25: =Donnees!F25 -> Partie 7 | H25: Signature : | I25: =_xlfn.TEXTJOIN(";",TRUE,B26:E27) -> Marc;Raphael;Guilhem;Sebastien;-235;-79;275;39
A26: Nom joueur | B26: Marc | C26: Raphael | D26: Guilhem | E26: Sebastien | F26: 45906.697 | H26: Check identique : | I26: {=IF(AND(Donnees!B25:F28=Check!B25:F28),"Identique","PAS IDENTIQUE")} -> Identique | J26: Check double noms : | K26: {=IF(MAX(COUNTIF(B26:E26,B26:E26)) > 1, "JOUEUR EN DOUBLE", "Pas de doublons")} -> Pas de doublons
A27: Mini-points | B27: -235 | C27: -79 | D27: 275 | E27: 39 | H27: Check doublons partie : | I27: =IF(COUNTIF(I$1:I26,I25)>1,"DOUBLON LIGNE " & MATCH(I25,I$1:I26,0),"Pas de doublons") -> Pas de doublons | J27: Check noms existants : | K27: {=IF(SUM(--(NOT(ISNUMBER(MATCH(B26:E26,'EMA points'!A:A,0))))) > 0, "NOM INEXISTANT", "Noms ok")} -> Noms ok
A28: Points de table | B28: =Donnees!B28 -> 0 | C28: =Donnees!C28 -> 1 | D28: =Donnees!D28 -> 3 | E28: =Donnees!E28 -> 2 | H28: Check score : | I28: =IF(SUM(B27:E27)=0, "Score ok", "SOMME NON NULLE") -> Score ok
A29: Vent | B29: Est | C29: Sud | D29: Ouest | E29: Nord | F29: =Donnees!F29 -> Partie 8 | H29: Signature : | I29: =_xlfn.TEXTJOIN(";",TRUE,B30:E31) -> Mathieu;Isabelle;Francoise;Christophe;-11;49;-55;17
A30: Nom joueur | B30: Mathieu | C30: Isabelle | D30: Francoise | E30: Christophe | F30: 45906.704 | H30: Check identique : | I30: {=IF(AND(Donnees!B29:F32=Check!B29:F32),"Identique","PAS IDENTIQUE")} -> Identique | J30: Check double noms : | K30: {=IF(MAX(COUNTIF(B30:E30,B30:E30)) > 1, "JOUEUR EN DOUBLE", "Pas de doublons")} -> Pas de doublons
A31: Mini-points | B31: -11 | C31: 49 | D31: -55 | E31: 17 | H31: Check doublons partie : | I31: =IF(COUNTIF(I$1:I30,I29)>1,"DOUBLON LIGNE " & MATCH(I29,I$1:I30,0),"Pas de doublons") -> Pas de doublons | J31: Check noms existants : | K31: {=IF(SUM(--(NOT(ISNUMBER(MATCH(B30:E30,'EMA points'!A:A,0))))) > 0, "NOM INEXISTANT", "Noms ok")} -> Noms ok
A32: Points de table | B32: =Donnees!B32 -> 1 | C32: =Donnees!C32 -> 3 | D32: =Donnees!D32 -> 0 | E32: =Donnees!E32 -> 2 | H32: Check score : | I32: =IF(SUM(B31:E31)=0, "Score ok", "SOMME NON NULLE") -> Score ok
A33: Vent | B33: Est | C33: Sud | D33: Ouest | E33: Nord | F33: =Donnees!F33 -> Partie 9 | H33: Signature : | I33: =_xlfn.TEXTJOIN(";",TRUE,B34:E35) -> Binome;Marie;Christophe;Valerie D;130;-150;-37;57
A34: Nom joueur | B34: Binome | C34: Marie | D34: Christophe | E34: Valerie D | F34: 45906.856 | H34: Check identique : | I34: {=IF(AND(Donnees!B33:F36=Check!B33:F36),"Identique","PAS IDENTIQUE")} -> Identique | J34: Check double noms : | K34: {=IF(MAX(COUNTIF(B34:E34,B34:E34)) > 1, "JOUEUR EN DOUBLE", "Pas de doublons")} -> Pas de doublons
A35: Mini-points | B35: 130 | C35: -150 | D35: -37 | E35: 57 | H35: Check doublons partie : | I35: =IF(COUNTIF(I$1:I34,I33)>1,"DOUBLON LIGNE " & MATCH(I33,I$1:I34,0),"Pas de doublons") -> Pas de doublons | J35: Check noms existants : | K35: {=IF(SUM(--(NOT(ISNUMBER(MATCH(B34:E34,'EMA points'!A:A,0))))) > 0, "NOM INEXISTANT", "Noms ok")} -> Noms ok
A36: Points de table | B36: =Donnees!B36 -> 3 | C36: =Donnees!C36 -> 0 | D36: =Donnees!D36 -> 1 | E36: =Donnees!E36 -> 2 | H36: Check score : | I36: =IF(SUM(B35:E35)=0, "Score ok", "SOMME NON NULLE") -> Score ok
A37: Vent | B37: Est | C37: Sud | D37: Ouest | E37: Nord | F37: =Donnees!F37 -> Partie 10 | H37: Signature : | I37: =_xlfn.TEXTJOIN(";",TRUE,B38:E39) -> Jean-Michel;Richard;Sebastien;Laurence;-98;161;-164;101
A38: Nom joueur | B38: Jean-Michel | C38: Richard | D38: Sebastien | E38: Laurence | F38: 45913.594 | H38: Check identique : | I38: {=IF(AND(Donnees!B37:F40=Check!B37:F40),"Identique","PAS IDENTIQUE")} -> Identique | J38: Check double noms : | K38: {=IF(MAX(COUNTIF(B38:E38,B38:E38)) > 1, "JOUEUR EN DOUBLE", "Pas de doublons")} -> Pas de doublons
A39: Mini-points | B39: -98 | C39: 161 | D39: -164 | E39: 101 | H39: Check doublons partie : | I39: =IF(COUNTIF(I$1:I38,I37)>1,"DOUBLON LIGNE " & MATCH(I37,I$1:I38,0),"Pas de doublons") -> Pas de doublons | J39: Check noms existants : | K39: {=IF(SUM(--(NOT(ISNUMBER(MATCH(B38:E38,'EMA points'!A:A,0))))) > 0, "NOM INEXISTANT", "Noms ok")} -> Noms ok
A40: Points de table | B40: =Donnees!B40 -> 1 | C40: =Donnees!C40 -> 3 | D40: =Donnees!D40 -> 0 | E40: =Donnees!E40 -> 2 | H40: Check score : | I40: =IF(SUM(B39:E39)=0, "Score ok", "SOMME NON NULLE") -> Score ok
...

Sheet EMA points
D1: 45901 | I1: 45931 | N1: 45962
A2: Noms | B2: Elo base | C2: EMA base | D2: Nb parties | E2: Elo | F2: Placement | G2: EMA gain | H2: EMA | I2: Nb parties | J2: Elo | K2: Placement | L2: EMA gain | M2: EMA | N2: Nb parties | O2: Elo | P2: Placement | Q2: EMA gain | R2: EMA
A3: Isabelle | B3: 980.345 | C3: 0 | D3: {=_xlfn.LET( _xlpm.dates, INDEX('Elo calculation'!$C:$C, _xlfn.SEQUENCE(COUNTA('Elo calculation'!$C:$C)-2,1,2,4)), _xlpm.pts, INDEX('Elo calculation'!$A:$ZZ, _xlfn.SEQUENCE(COUNTA('Elo calculation'!$C:$C)-2,1,3,4), MATCH($A3,'Elo calculation'!$1:$1,0)), _xlpm.nbparties, SUMPRODUCT(--(_xlpm.dates <= EOMONTH(D$1,0)), --(_xlpm.dates >= D$1), --(_xlpm.pts <> "")), _xlpm.nbparties )} -> 11 | E3: {=_xlfn.LET( _xlpm.seq, _xlfn.SEQUENCE(COUNTA('Elo calculation'!$A:$A)/4, 1, 2, 4), _xlpm.dates, INDEX('Elo calculation'!$C:$C, _xlpm.seq), _xlpm.limite, EOMONTH(D$1,0), _xlpm.ligdate, MAX(IF(_xlpm.dates <= _xlpm.limite, _xlpm.seq, 0)), _xlpm.coljoueur, MATCH($A3, 'Elo calculation'!$1:$1, 0), INDEX('Elo calculation'!$A:$ZZ, _xlpm.ligdate + 4, _xlpm.coljoueur) )} -> 1071.9165 | F3: {=_xlfn.LET( _xlpm.vals, _xlfn._xlws.FILTER(E:E, (D:D>0)*(ISNUMBER(E:E)), ""), _xlpm.nPlus, SUM(--(_xlpm.vals > E3)), _xlpm.nEgal, SUM(--(_xlpm.vals = E3)), _xlpm.res, 1 + _xlpm.nPlus + (_xlpm.nEgal - 1) / 2, IF(D3=0, "", _xlpm.res) )} -> 7 | G3: {=_xlfn.LET( _xlpm.ming, Constantes!$B$8, _xlpm.maxmma, Constantes!$B$6, _xlpm.minmma, Constantes!$B$7, _xlpm.maxp, MAX(_xlfn._xlws.FILTER(F:F, ISNUMBER(F:F))), _xlpm.place, IF(F3="", _xlpm.maxp, F3), MIN(_xlpm.ming,D3)/_xlpm.ming * ((_xlpm.maxp - _xlpm.place) / (_xlpm.maxp - 1) * (_xlpm.maxmma - _xlpm.minmma) + _xlpm.minmma) )} -> 392 | H3: =C3+G3 -> 392 | I3: {=_xlfn.LET( _xlpm.dates, INDEX('Elo calculation'!$C:$C, _xlfn.SEQUENCE(COUNTA('Elo calculation'!$C:$C)-2,1,2,4)), _xlpm.pts, INDEX('Elo calculation'!$A:$ZZ, _xlfn.SEQUENCE(COUNTA('Elo calculation'!$C:$C)-2,1,3,4), MATCH($A3,'Elo calculation'!$1:$1,0)), _xlpm.nbparties, SUMPRODUCT(--(_xlpm.dates <= EOMONTH(I$1,0)), --(_xlpm.dates >= I$1), --(_xlpm.pts <> "")), _xlpm.nbparties )} -> 10 | J3: {=_xlfn.LET( _xlpm.seq, _xlfn.SEQUENCE(COUNTA('Elo calculation'!$A:$A)/4, 1, 2, 4), _xlpm.dates, INDEX('Elo calculation'!$C:$C, _xlpm.seq), _xlpm.limite, EOMONTH(I$1,0), _xlpm.ligdate, MAX(IF(_xlpm.dates <= _xlpm.limite, _xlpm.seq, 0)), _xlpm.coljoueur, MATCH($A3, 'Elo calculation'!$1:$1, 0), INDEX('Elo calculation'!$A:$ZZ, _xlpm.ligdate + 4, _xlpm.coljoueur) )} -> 968.82938 | K3: {=_xlfn.LET( _xlpm.vals, _xlfn._xlws.FILTER(J:J, (I:I>0)*(ISNUMBER(J:J)), ""), _xlpm.nPlus, SUM(--(_xlpm.vals > J3)), _xlpm.nEgal, SUM(--(_xlpm.vals = J3)), _xlpm.res, 1 + _xlpm.nPlus + (_xlpm.nEgal - 1) / 2, IF(I3=0, "", _xlpm.res) )} -> 21 | L3: {=_xlfn.LET( _xlpm.ming, Constantes!$B$8, _xlpm.maxmma, Constantes!$B$6, _xlpm.minmma, Constantes!$B$7, _xlpm.maxp, MAX(_xlfn._xlws.FILTER(K:K, ISNUMBER(K:K))), _xlpm.place, IF(K3="", _xlpm.maxp, K3), MIN(_xlpm.ming,I3)/_xlpm.ming * ((_xlpm.maxp - _xlpm.place) / (_xlpm.maxp - 1) * (_xlpm.maxmma - _xlpm.minmma) + _xlpm.minmma) )} -> 235.29412 | M3: =H3+L3 -> 627.29412 | N3: {=_xlfn.LET( _xlpm.dates, INDEX('Elo calculation'!$C:$C, _xlfn.SEQUENCE(COUNTA('Elo calculation'!$C:$C)-2,1,2,4)), _xlpm.pts, INDEX('Elo calculation'!$A:$ZZ, _xlfn.SEQUENCE(COUNTA('Elo calculation'!$C:$C)-2,1,3,4), MATCH($A3,'Elo calculation'!$1:$1,0)), _xlpm.nbparties, SUMPRODUCT(--(_xlpm.dates <= EOMONTH(N$1,0)), --(_xlpm.dates >= N$1), --(_xlpm.pts <> "")), _xlpm.nbparties )} -> 3 | O3: {=_xlfn.LET( _xlpm.seq, _xlfn.SEQUENCE(COUNTA('Elo calculation'!$A:$A)/4, 1, 2, 4), _xlpm.dates, INDEX('Elo calculation'!$C:$C, _xlpm.seq), _xlpm.limite, EOMONTH(N$1,0), _xlpm.ligdate, MAX(IF(_xlpm.dates <= _xlpm.limite, _xlpm.seq, 0)), _xlpm.coljoueur, MATCH($A3, 'Elo calculation'!$1:$1, 0), INDEX('Elo calculation'!$A:$ZZ, _xlpm.ligdate + 4, _xlpm.coljoueur) )} -> 970.88542 | P3: {=_xlfn.LET( _xlpm.vals, _xlfn._xlws.FILTER(O:O, (N:N>0)*(ISNUMBER(O:O)), ""), _xlpm.nPlus, SUM(--(_xlpm.vals > O3)), _xlpm.nEgal, SUM(--(_xlpm.vals = O3)), _xlpm.res, 1 + _xlpm.nPlus + (_xlpm.nEgal - 1) / 2, IF(N3=0, "", _xlpm.res) )} -> 14 | Q3: {=_xlfn.LET( _xlpm.ming, Constantes!$B$8, _xlpm.maxmma, Constantes!$B$6, _xlpm.minmma, Constantes!$B$7, _xlpm.maxp, MAX(_xlfn._xlws.FILTER(P:P, ISNUMBER(P:P))), _xlpm.place, IF(P3="", _xlpm.maxp, P3), MIN(_xlpm.ming,N3)/_xlpm.ming * ((_xlpm.maxp - _xlpm.place) / (_xlpm.maxp - 1) * (_xlpm.maxmma - _xlpm.minmma) + _xlpm.minmma) )} -> 184.23913 | R3: =M3+Q3 -> 811.53325
A4: Guilhem | B4: 1083.54 | C4: 0 | D4: {=_xlfn.LET( _xlpm.dates, INDEX('Elo calculation'!$C:$C, _xlfn.SEQUENCE(COUNTA('Elo calculation'!$C:$C)-2,1,2,4)), _xlpm.pts, INDEX('Elo calculation'!$A:$ZZ, _xlfn.SEQUENCE(COUNTA('Elo calculation'!$C:$C)-2,1,3,4), MATCH($A4,'Elo calculation'!$1:$1,0)), _xlpm.nbparties, SUMPRODUCT(--(_xlpm.dates <= EOMONTH(D$1,0)), --(_xlpm.dates >= D$1), --(_xlpm.pts <> "")), _xlpm.nbparties )} -> 13 | E4: {=_xlfn.LET( _xlpm.seq, _xlfn.SEQUENCE(COUNTA('Elo calculation'!$A:$A)/4, 1, 2, 4), _xlpm.dates, INDEX('Elo calculation'!$C:$C, _xlpm.seq), _xlpm.limite, EOMONTH(D$1,0), _xlpm.ligdate, MAX(IF(_xlpm.dates <= _xlpm.limite, _xlpm.seq, 0)), _xlpm.coljoueur, MATCH($A4, 'Elo calculation'!$1:$1, 0), INDEX('Elo calculation'!$A:$ZZ, _xlpm.ligdate + 4, _xlpm.coljoueur) )} -> 1105.3751 | F4: {=_xlfn.LET( _xlpm.vals, _xlfn._xlws.FILTER(E:E, (D:D>0)*(ISNUMBER(E:E)), ""), _xlpm.nPlus, SUM(--(_xlpm.vals > E4)), _xlpm.nEgal, SUM(--(_xlpm.vals = E4)), _xlpm.res, 1 + _xlpm.nPlus + (_xlpm.nEgal - 1) / 2, IF(D4=0, "", _xlpm.res) )} -> 4 | G4: {=_xlfn.LET( _xlpm.ming, Constantes!$B$8, _xlpm.maxmma, Constantes!$B$6, _xlpm.minmma, Constantes!$B$7, _xlpm.maxp, MAX(_xlfn._xlws.FILTER(F:F, ISNUMBER(F:F))), _xlpm.place, IF(F4="", _xlpm.maxp, F4), MIN(_xlpm.ming,D4)/_xlpm.ming * ((_xlpm.maxp - _xlpm.place) / (_xlpm.maxp - 1) * (_xlpm.maxmma - _xlpm.minmma) + _xlpm.minmma) )} -> 446 | H4: =C4+G4 -> 446 | I4: {=_xlfn.LET( _xlpm.dates, INDEX('Elo calculation'!$C:$C, _xlfn.SEQUENCE(COUNTA('Elo calculation'!$C:$C)-2,1,2,4)), _xlpm.pts, INDEX('Elo calculation'!$A:$ZZ, _xlfn.SEQUENCE(COUNTA('Elo calculation'!$C:$C)-2,1,3,4), MATCH($A4,'Elo calculation'!$1:$1,0)), _xlpm.nbparties, SUMPRODUCT(--(_xlpm.dates <= EOMONTH(I$1,0)), --(_xlpm.dates >= I$1), --(_xlpm.pts <> "")), _xlpm.nbparties )} -> 11 | J4: {=_xlfn.LET( _xlpm.seq, _xlfn.SEQUENCE(COUNTA('Elo calculation'!$A:$A)/4, 1, 2, 4), _xlpm.dates, INDEX('Elo calculation'!$C:$C, _xlpm.seq), _xlpm.limite, EOMONTH(I$1,0), _xlpm.ligdate, MAX(IF(_xlpm.dates <= _xlpm.limite, _xlpm.seq, 0)), _xlpm.coljoueur, MATCH($A4, 'Elo calculation'!$1:$1, 0), INDEX('Elo calculation'!$A:$ZZ, _xlpm.ligdate + 4, _xlpm.coljoueur) )} -> 1196.4196 | K4: {=_xlfn.LET( _xlpm.vals, _xlfn._xlws.FILTER(J:J, (I:I>0)*(ISNUMBER(J:J)), ""), _xlpm.nPlus, SUM(--(_xlpm.vals > J4)), _xlpm.nEgal, SUM(--(_xlpm.vals = J4)), _xlpm.res, 1 + _xlpm.nPlus + (_xlpm.nEgal - 1) / 2, IF(I4=0, "", _xlpm.res) )} -> 1 | L4: {=_xlfn.LET( _xlpm.ming, Constantes!$B$8, _xlpm.maxmma, Constantes!$B$6, _xlpm.minmma, Constantes!$B$7, _xlpm.maxp, MAX(_xlfn._xlws.FILTER(K:K, ISNUMBER(K:K))), _xlpm.place, IF(K4="", _xlpm.maxp, K4), MIN(_xlpm.ming,I4)/_xlpm.ming * ((_xlpm.maxp - _xlpm.place) / (_xlpm.maxp - 1) * (_xlpm.maxmma - _xlpm.minmma) + _xlpm.minmma) )} -> 500 | M4: =H4+L4 -> 946 | N4: {=_xlfn.LET( _xlpm.dates, INDEX('Elo calculation'!$C:$C, _xlfn.SEQUENCE(COUNTA('Elo calculation'!$C:$C)-2,1,2,4)), _xlpm.pts, INDEX('Elo calculation'!$A:$ZZ, _xlfn.SEQUENCE(COUNTA('Elo calculation'!$C:$C)-2,1,3,4), MATCH($A4,'Elo calculation'!$1:$1,0)), _xlpm.nbparties, SUMPRODUCT(--(_xlpm.dates <= EOMONTH(N$1,0)), --(_xlpm.dates >= N$1), --(_xlpm.pts <> "")), _xlpm.nbparties )} -> 2 | O4: {=_xlfn.LET( _xlpm.seq, _xlfn.SEQUENCE(COUNTA('Elo calculation'!$A:$A)/4, 1, 2, 4), _xlpm.dates, INDEX('Elo calculation'!$C:$C, _xlpm.seq), _xlpm.limite, EOMONTH(N$1,0), _xlpm.ligdate, MAX(IF(_xlpm.dates <= _xlpm.limite, _xlpm.seq, 0)), _xlpm.coljoueur, MATCH($A4, 'Elo calculation'!$1:$1, 0), INDEX('Elo calculation'!$A:$ZZ, _xlpm.ligdate + 4, _xlpm.coljoueur) )} -> 1229.0521 | P4: {=_xlfn.LET( _xlpm.vals, _xlfn._xlws.FILTER(O:O, (N:N>0)*(ISNUMBER(O:O)), ""), _xlpm.nPlus, SUM(--(_xlpm.vals > O4)), _xlpm.nEgal, SUM(--(_xlpm.vals = O4)), _xlpm.res, 1 + _xlpm.nPlus + (_xlpm.nEgal - 1) / 2, IF(N4=0, "", _xlpm.res) )} -> 1 | Q4: {=_xlfn.LET( _xlpm.ming, Constantes!$B$8, _xlpm.maxmma, Constantes!$B$6, _xlpm.minmma, Constantes!$B$7, _xlpm.maxp, MAX(_xlfn._xlws.FILTER(P:P, ISNUMBER(P:P))), _xlpm.place, IF(P4="", _xlpm.maxp, P4), MIN(_xlpm.ming,N4)/_xlpm.ming * ((_xlpm.maxp - _xlpm.place) / (_xlpm.maxp - 1) * (_xlpm.maxmma - _xlpm.minmma) + _xlpm.minmma) )} -> 250 | R4: =M4+Q4 -> 1196
A5: Marc | B5: 903.97 | C5: 0 | D5: {=_xlfn.LET( _xlpm.dates, INDEX('Elo calculation'!$C:$C, _xlfn.SEQUENCE(COUNTA('Elo calculation'!$C:$C)-2,1,2,4)), _xlpm.pts, INDEX('Elo calculation'!$A:$ZZ, _xlfn.SEQUENCE(COUNTA('Elo calculation'!$C:$C)-2,1,3,4), MATCH($A5,'Elo calculation'!$1:$1,0)), _xlpm.nbparties, SUMPRODUCT(--(_xlpm.dates <= EOMONTH(D$1,0)), --(_xlpm.dates >= D$1), --(_xlpm.pts <> "")), _xlpm.nbparties )} -> 14 | E5: {=_xlfn.LET( _xlpm.seq, _xlfn.SEQUENCE(COUNTA('Elo calculation'!$A:$A)/4, 1, 2, 4), _xlpm.dates, INDEX('Elo calculation'!$C:$C, _xlpm.seq), _xlpm.limite, EOMONTH(D$1,0), _xlpm.ligdate, MAX(IF(_xlpm.dates <= _xlpm.limite, _xlpm.seq, 0)), _xlpm.coljoueur, MATCH($A5, 'Elo calculation'!$1:$1, 0), INDEX('Elo calculation'!$A:$ZZ, _xlpm.ligdate + 4, _xlpm.coljoueur) )} -> 839.76438 | F5: {=_xlfn.LET( _xlpm.vals, _xlfn._xlws.FILTER(E:E, (D:D>0)*(ISNUMBER(E:E)), ""), _xlpm.nPlus, SUM(--(_xlpm.vals > E5)), _xlpm.nEgal, SUM(--(_xlpm.vals = E5)), _xlpm.res, 1 + _xlpm.nPlus + (_xlpm.nEgal - 1) / 2, IF(D5=0, "", _xlpm.res) )} -> 25 | G5: {=_xlfn.LET( _xlpm.ming, Constantes!$B$8, _xlpm.maxmma, Constantes!$B$6, _xlpm.minmma, Constantes!$B$7, _xlpm.maxp, MAX(_xlfn._xlws.FILTER(F:F, ISNUMBER(F:F))), _xlpm.place, IF(F5="", _xlpm.maxp, F5), MIN(_xlpm.ming,D5)/_xlpm.ming * ((_xlpm.maxp - _xlpm.place) / (_xlpm.maxp - 1) * (_xlpm.maxmma - _xlpm.minmma) + _xlpm.minmma) )} -> 68 | H5: =C5+G5 -> 68 | I5: {=_xlfn.LET( _xlpm.dates, INDEX('Elo calculation'!$C:$C, _xlfn.SEQUENCE(COUNTA('Elo calculation'!$C:$C)-2,1,2,4)), _xlpm.pts, INDEX('Elo calculation'!$A:$ZZ, _xlfn.SEQUENCE(COUNTA('Elo calculation'!$C:$C)-2,1,3,4), MATCH($A5,'Elo calculation'!$1:$1,0)), _xlpm.nbparties, SUMPRODUCT(--(_xlpm.dates <= EOMONTH(I$1,0)), --(_xlpm.dates >= I$1), --(_xlpm.pts <> "")), _xlpm.nbparties )} -> 11 | J5: {=_xlfn.LET( _xlpm.seq, _xlfn.SEQUENCE(COUNTA('Elo calculation'!$A:$A)/4, 1, 2, 4), _xlpm.dates, INDEX('Elo calculation'!$C:$C, _xlpm.seq), _xlpm.limite, EOMONTH(I$1,0), _xlpm.ligdate, MAX(IF(_xlpm.dates <= _xlpm.limite, _xlpm.seq, 0)), _xlpm.coljoueur, MATCH($A5, 'Elo calculation'!$1:$1, 0), INDEX('Elo calculation'!$A:$ZZ, _xlpm.ligdate + 4, _xlpm.coljoueur) )} -> 911.88358 | K5: {=_xlfn.LET( _xlpm.vals, _xlfn._xlws.FILTER(J:J, (I:I>0)*(ISNUMBER(J:J)), ""), _xlpm.nPlus, SUM(--(_xlpm.vals > J5)), _xlpm.nEgal, SUM(--(_xlpm.vals = J5)), _xlpm.res, 1 + _xlpm.nPlus + (_xlpm.nEgal - 1) / 2, IF(I5=0, "", _xlpm.res) )} -> 28 | L5: {=_xlfn.LET( _xlpm.ming, Constantes!$B$8, _xlpm.maxmma, Constantes!$B$6, _xlpm.minmma, Constantes!$B$7, _xlpm.maxp, MAX(_xlfn._xlws.FILTER(K:K, ISNUMBER(K:K))), _xlpm.place, IF(K5="", _xlpm.maxp, K5), MIN(_xlpm.ming,I5)/_xlpm.ming * ((_xlpm.maxp - _xlpm.place) / (_xlpm.maxp - 1) * (_xlpm.maxmma - _xlpm.minmma) + _xlpm.minmma) )} -> 142.64706 | M5: =H5+L5 -> 210.64706 | N5: {=_xlfn.LET( _xlpm.dates, INDEX('Elo calculation'!$C:$C, _xlfn.SEQUENCE(COUNTA('Elo calculation'!$C:$C)-2,1,2,4)), _xlpm.pts, INDEX('Elo calculation'!$A:$ZZ, _xlfn.SEQUENCE(COUNTA('Elo calculation'!$C:$C)-2,1,3,4), MATCH($A5,'Elo calculation'!$1:$1,0)), _xlpm.nbparties, SUMPRODUCT(--(_xlpm.dates <= EOMONTH(N$1,0)), --(_xlpm.dates >= N$1), --(_xlpm.pts <> "")), _xlpm.nbparties )} -> 0 | O5: {=_xlfn.LET( _xlpm.seq, _xlfn.SEQUENCE(COUNTA('Elo calculation'!$A:$A)/4, 1, 2, 4), _xlpm.dates, INDEX('Elo calculation'!$C:$C, _xlpm.seq), _xlpm.limite, EOMONTH(N$1,0), _xlpm.ligdate, MAX(IF(_xlpm.dates <= _xlpm.limite, _xlpm.seq, 0)), _xlpm.coljoueur, MATCH($A5, 'Elo calculation'!$1:$1, 0), INDEX('Elo calculation'!$A:$ZZ, _xlpm.ligdate + 4, _xlpm.coljoueur) )} -> 911.88358 | P5: {=_xlfn.LET( _xlpm.vals, _xlfn._xlws.FILTER(O:O, (N:N>0)*(ISNUMBER(O:O)), ""), _xlpm.nPlus, SUM(--(_xlpm.vals > O5)), _xlpm.nEgal, SUM(--(_xlpm.vals = O5)), _xlpm.res, 1 + _xlpm.nPlus + (_xlpm.nEgal - 1) / 2, IF(N5=0, "", _xlpm.res) )} | Q5: {=_xlfn.LET( _xlpm.ming, Constantes!$B$8, _xlpm.maxmma, Constantes!$B$6, _xlpm.minmma, Constantes!$B$7, _xlpm.maxp, MAX(_xlfn._xlws.FILTER(P:P, ISNUMBER(P:P))), _xlpm.place, IF(P5="", _xlpm.maxp, P5), MIN(_xlpm.ming,N5)/_xlpm.ming * ((_xlpm.maxp - _xlpm.place) / (_xlpm.maxp - 1) * (_xlpm.maxmma - _xlpm.minmma) + _xlpm.minmma) )} -> 0 | R5: =M5+Q5 -> 210.64706
A6: Christophe | B6: 1068.34 | C6: 0 | D6: {=_xlfn.LET( _xlpm.dates, INDEX('Elo calculation'!$C:$C, _xlfn.SEQUENCE(COUNTA('Elo calculation'!$C:$C)-2,1,2,4)), _xlpm.pts, INDEX('Elo calculation'!$A:$ZZ, _xlfn.SEQUENCE(COUNTA('Elo calculation'!$C:$C)-2,1,3,4), MATCH($A6,'Elo calculation'!$1:$1,0)), _xlpm.nbparties, SUMPRODUCT(--(_xlpm.dates <= EOMONTH(D$1,0)), --(_xlpm.dates >= D$1), --(_xlpm.pts <> "")), _xlpm.nbparties )} -> 16 | E6: {=_xlfn.LET( _xlpm.seq, _xlfn.SEQUENCE(COUNTA('Elo calculation'!$A:$A)/4, 1, 2, 4), _xlpm.dates, INDEX('Elo calculation'!$C:$C, _xlpm.seq), _xlpm.limite, EOMONTH(D$1,0), _xlpm.ligdate, MAX(IF(_xlpm.dates <= _xlpm.limite, _xlpm.seq, 0)), _xlpm.coljoueur, MATCH($A6, 'Elo calculation'!$1:$1, 0), INDEX('Elo calculation'!$A:$ZZ, _xlpm.ligdate + 4, _xlpm.coljoueur) )} -> 1040.3895 | F6: {=_xlfn.LET( _xlpm.vals, _xlfn._xlws.FILTER(E:E, (D:D>0)*(ISNUMBER(E:E)), ""), _xlpm.nPlus, SUM(--(_xlpm.vals > E6)), _xlpm.nEgal, SUM(--(_xlpm.vals = E6)), _xlpm.res, 1 + _xlpm.nPlus + (_xlpm.nEgal - 1) / 2, IF(D6=0, "", _xlpm.res) )} -> 10 | G6: {=_xlfn.LET( _xlpm.ming, Constantes!$B$8, _xlpm.maxmma, Constantes!$B$6, _xlpm.minmma, Constantes!$B$7, _xlpm.maxp, MAX(_xlfn._xlws.FILTER(F:F, ISNUMBER(F:F))), _xlpm.place, IF(F6="", _xlpm.maxp, F6), MIN(_xlpm.ming,D6)/_xlpm.ming * ((_xlpm.maxp - _xlpm.place) / (_xlpm.maxp - 1) * (_xlpm.maxmma - _xlpm.minmma) + _xlpm.minmma) )} -> 338 | H6: =C6+G6 -> 338 | I6: {=_xlfn.LET( _xlpm.dates, INDEX('Elo calculation'!$C:$C, _xlfn.SEQUENCE(COUNTA('Elo calculation'!$C:$C)-2,1,2,4)), _xlpm.pts, INDEX('Elo calculation'!$A:$ZZ, _xlfn.SEQUENCE(COUNTA('Elo calculation'!$C:$C)-2,1,3,4), MATCH($A6,'Elo calculation'!$1:$1,0)), _xlpm.nbparties, SUMPRODUCT(--(_xlpm.dates <= EOMONTH(I$1,0)), --(_xlpm.dates >= I$1), --(_xlpm.pts <> "")), _xlpm.nbparties )} -> 14 | J6: {=_xlfn.LET( _xlpm.seq, _xlfn.SEQUENCE(COUNTA('Elo calculation'!$A:$A)/4, 1, 2, 4), _xlpm.dates, INDEX('Elo calculation'!$C:$C, _xlpm.seq), _xlpm.limite, EOMONTH(I$1,0), _xlpm.ligdate, MAX(IF(_xlpm.dates <= _xlpm.limite, _xlpm.seq, 0)), _xlpm.coljoueur, MATCH($A6, 'Elo calculation'!$1:$1, 0), INDEX('Elo calculation'!$A:$ZZ, _xlpm.ligdate + 4, _xlpm.coljoueur) )} -> 1061.9526 | K6: {=_xlfn.LET( _xlpm.vals, _xlfn._xlws.FILTER(J:J, (I:I>0)*(ISNUMBER(J:J)), ""), _xlpm.nPlus, SUM(--(_xlpm.vals > J6)), _xlpm.nEgal, SUM(--(_xlpm.vals = J6)), _xlpm.res, 1 + _xlpm.nPlus + (_xlpm.nEgal - 1) / 2, IF(I6=0, "", _xlpm.res) )} -> 9 | L6: {=_xlfn.LET( _xlpm.ming, Constantes!$B$8, _xlpm.maxmma, Constantes!$B$6, _xlpm.minmma, Constantes!$B$7, _xlpm.maxp, MAX(_xlfn._xlws.FILTER(K:K, ISNUMBER(K:K))), _xlpm.place, IF(K6="", _xlpm.maxp, K6), MIN(_xlpm.ming,I6)/_xlpm.ming * ((_xlpm.maxp - _xlpm.place) / (_xlpm.maxp - 1) * (_xlpm.maxmma - _xlpm.minmma) + _xlpm.minmma) )} -> 394.11765 | M6: =H6+L6 -> 732.11765 | N6: {=_xlfn.LET( _xlpm.dates, INDEX('Elo calculation'!$C:$C, _xlfn.SEQUENCE(COUNTA('Elo calculation'!$C:$C)-2,1,2,4)), _xlpm.pts, INDEX('Elo calculation'!$A:$ZZ, _xlfn.SEQUENCE(COUNTA('Elo calculation'!$C:$C)-2,1,3,4), MATCH($A6,'Elo calculation'!$1:$1,0)), _xlpm.nbparties, SUMPRODUCT(--(_xlpm.dates <= EOMONTH(N$1,0)), --(_xlpm.dates >= N$1), --(_xlpm.pts <> "")), _xlpm.nbparties )} -> 3 | O6: {=_xlfn.LET( _xlpm.seq, _xlfn.SEQUENCE(COUNTA('Elo calculation'!$A:$A)/4, 1, 2, 4), _xlpm.dates, INDEX('Elo calculation'!$C:$C, _xlpm.seq), _xlpm.limite, EOMONTH(N$1,0), _xlpm.ligdate, MAX(IF(_xlpm.dates <= _xlpm.limite, _xlpm.seq, 0)), _xlpm.coljoueur, MATCH($A6, 'Elo calculation'!$1:$1, 0), INDEX('Elo calculation'!$A:$ZZ, _xlpm.ligdate + 4, _xlpm.coljoueur) )} -> 1021.5669 | P6: {=_xlfn.LET( _xlpm.vals, _xlfn._xlws.FILTER(O:O, (N:N>0)*(ISNUMBER(O:O)), ""), _xlpm.nPlus, SUM(--(_xlpm.vals > O6)), _xlpm.nEgal, SUM(--(_xlpm.vals = O6)), _xlpm.res, 1 + _xlpm.nPlus + (_xlpm.nEgal - 1) / 2, IF(N6=0, "", _xlpm.res) )} -> 10 | Q6: {=_xlfn.LET( _xlpm.ming, Constantes!$B$8, _xlpm.maxmma, Constantes!$B$6, _xlpm.minmma, Constantes!$B$7, _xlpm.maxp, MAX(_xlfn._xlws.FILTER(P:P, ISNUMBER(P:P))), _xlpm.place, IF(P6="", _xlpm.maxp, P6), MIN(_xlpm.ming,N6)/_xlpm.ming * ((_xlpm.maxp - _xlpm.place) / (_xlpm.maxp - 1) * (_xlpm.maxmma - _xlpm.minmma) + _xlpm.minmma) )} -> 242.93478 | R6: =M6+Q6 -> 975.05243
A7: Raphael | B7: 1075.79 | C7: 0 | D7: {=_xlfn.LET( _xlpm.dates, INDEX('Elo calculation'!$C:$C, _xlfn.SEQUENCE(COUNTA('Elo calculation'!$C:$C)-2,1,2,4)), _xlpm.pts, INDEX('Elo calculation'!$A:$ZZ, _xlfn.SEQUENCE(COUNTA('Elo calculation'!$C:$C)-2,1,3,4), MATCH($A7,'Elo calculation'!$1:$1,0)), _xlpm.nbparties, SUMPRODUCT(--(_xlpm.dates <= EOMONTH(D$1,0)), --(_xlpm.dates >= D$1), --(_xlpm.pts <> "")), _xlpm.nbparties )} -> 6 | E7: {=_xlfn.LET( _xlpm.seq, _xlfn.SEQUENCE(COUNTA('Elo calculation'!$A:$A)/4, 1, 2, 4), _xlpm.dates, INDEX('Elo calculation'!$C:$C, _xlpm.seq), _xlpm.limite, EOMONTH(D$1,0), _xlpm.ligdate, MAX(IF(_xlpm.dates <= _xlpm.limite, _xlpm.seq, 0)), _xlpm.coljoueur, MATCH($A7, 'Elo calculation'!$1:$1, 0), INDEX('Elo calculation'!$A:$ZZ, _xlpm.ligdate + 4, _xlpm.coljoueur) )} -> 1043.8545 | F7: {=_xlfn.LET( _xlpm.vals, _xlfn._xlws.FILTER(E:E, (D:D>0)*(ISNUMBER(E:E)), ""), _xlpm.nPlus, SUM(--(_xlpm.vals > E7)), _xlpm.nEgal, SUM(--(_xlpm.vals = E7)), _xlpm.res, 1 + _xlpm.nPlus + (_xlpm.nEgal - 1) / 2, IF(D7=0, "", _xlpm.res) )} -> 9 | G7: {=_xlfn.LET( _xlpm.ming, Constantes!$B$8, _xlpm.maxmma, Constantes!$B$6, _xlpm.minmma, Constantes!$B$7, _xlpm.maxp, MAX(_xlfn._xlws.FILTER(F:F, ISNUMBER(F:F))), _xlpm.place, IF(F7="", _xlpm.maxp, F7), MIN(_xlpm.ming,D7)/_xlpm.ming * ((_xlpm.maxp - _xlpm.place) / (_xlpm.maxp - 1) * (_xlpm.maxmma - _xlpm.minmma) + _xlpm.minmma) )} -> 356 | H7: =C7+G7 -> 356 | I7: {=_xlfn.LET( _xlpm.dates, INDEX('Elo calculation'!$C:$C, _xlfn.SEQUENCE(COUNTA('Elo calculation'!$C:$C)-2,1,2,4)), _xlpm.pts, INDEX('Elo calculation'!$A:$ZZ, _xlfn.SEQUENCE(COUNTA('Elo calculation'!$C:$C)-2,1,3,4), MATCH($A7,'Elo calculation'!$1:$1,0)), _xlpm.nbparties, SUMPRODUCT(--(_xlpm.dates <= EOMONTH(I$1,0)), --(_xlpm.dates >= I$1), --(_xlpm.pts <> "")), _xlpm.nbparties )} -> 7 | J7: {=_xlfn.LET( _xlpm.seq, _xlfn.SEQUENCE(COUNTA('Elo calculation'!$A:$A)/4, 1, 2, 4), _xlpm.dates, INDEX('Elo calculation'!$C:$C, _xlpm.seq), _xlpm.limite, EOMONTH(I$1,0), _xlpm.ligdate, MAX(IF(_xlpm.dates <= _xlpm.limite, _xlpm.seq, 0)), _xlpm.coljoueur, MATCH($A7, 'Elo calculation'!$1:$1, 0), INDEX('Elo calculation'!$A:$ZZ, _xlpm.ligdate + 4, _xlpm.coljoueur) )} -> 1121.8561 | K7: {=_xlfn.LET( _xlpm.vals, _xlfn._xlws.FILTER(J:J, (I:I>0)*(ISNUMBER(J:J)), ""), _xlpm.nPlus, SUM(--(_xlpm.vals > J7)), _xlpm.nEgal, SUM(--(_xlpm.vals = J7)), _xlpm.res, 1 + _xlpm.nPlus + (_xlpm.nEgal - 1) / 2, IF(I7=0, "", _xlpm.res) )} -> 4 | L7: {=_xlfn.LET( _xlpm.ming, Constantes!$B$8, _xlpm.maxmma, Constantes!$B$6, _xlpm.minmma, Constantes!$B$7, _xlpm.maxp, MAX(_xlfn._xlws.FILTER(K:K, ISNUMBER(K:K))), _xlpm.place, IF(K7="", _xlpm.maxp, K7), MIN(_xlpm.ming,I7)/_xlpm.ming * ((_xlpm.maxp - _xlpm.place) / (_xlpm.maxp - 1) * (_xlpm.maxmma - _xlpm.minmma) + _xlpm.minmma) )} -> 460.29412 | M7: =H7+L7 -> 816.29412 | N7: {=_xlfn.LET( _xlpm.dates, INDEX('Elo calculation'!$C:$C, _xlfn.SEQUENCE(COUNTA('Elo calculation'!$C:$C)-2,1,2,4)), _xlpm.pts, INDEX('Elo calculation'!$A:$ZZ, _xlfn.SEQUENCE(COUNTA('Elo calculation'!$C:$C)-2,1,3,4), MATCH($A7,'Elo calculation'!$1:$1,0)), _xlpm.nbparties, SUMPRODUCT(--(_xlpm.dates <= EOMONTH(N$1,0)), --(_xlpm.dates >= N$1), --(_xlpm.pts <> "")), _xlpm.nbparties )} -> 4 | O7: {=_xlfn.LET( _xlpm.seq, _xlfn.SEQUENCE(COUNTA('Elo calculation'!$A:$A)/4, 1, 2, 4), _xlpm.dates, INDEX('Elo calculation'!$C:$C, _xlpm.seq), _xlpm.limite, EOMONTH(N$1,0), _xlpm.ligdate, MAX(IF(_xlpm.dates <= _xlpm.limite, _xlpm.seq, 0)), _xlpm.coljoueur, MATCH($A7, 'Elo calculation'!$1:$1, 0), INDEX('Elo calculation'!$A:$ZZ, _xlpm.ligdate + 4, _xlpm.coljoueur) )} -> 1117.5251 | P7: {=_xlfn.LET( _xlpm.vals, _xlfn._xlws.FILTER(O:O, (N:N>0)*(ISNUMBER(O:O)), ""), _xlpm.nPlus, SUM(--(_xlpm.vals > O7)), _xlpm.nEgal, SUM(--(_xlpm.vals = O7)), _xlpm.res, 1 + _xlpm.nPlus + (_xlpm.nEgal - 1) / 2, IF(N7=0, "", _xlpm.res) )} -> 5 | Q7: {=_xlfn.LET( _xlpm.ming, Constantes!$B$8, _xlpm.maxmma, Constantes!$B$6, _xlpm.minmma, Constantes!$B$7, _xlpm.maxp, MAX(_xlfn._xlws.FILTER(P:P, ISNUMBER(P:P))), _xlpm.place, IF(P7="", _xlpm.maxp, P7), MIN(_xlpm.ming,N7)/_xlpm.ming * ((_xlpm.maxp - _xlpm.place) / (_xlpm.maxp - 1) * (_xlpm.maxmma - _xlpm.minmma) + _xlpm.minmma) )} -> 421.73913 | R7: =M7+Q7 -> 1238.0332
A8: Delphine | B8: 1000 | C8: 0 | D8: {=_xlfn.LET( _xlpm.dates, INDEX('Elo calculation'!$C:$C, _xlfn.SEQUENCE(COUNTA('Elo calculation'!$C:$C)-2,1,2,4)), _xlpm.pts, INDEX('Elo calculation'!$A:$ZZ, _xlfn.SEQUENCE(COUNTA('Elo calculation'!$C:$C)-2,1,3,4), MATCH($A8,'Elo calculation'!$1:$1,0)), _xlpm.nbparties, SUMPRODUCT(--(_xlpm.dates <= EOMONTH(D$1,0)), --(_xlpm.dates >= D$1), --(_xlpm.pts <> "")), _xlpm.nbparties )} -> 5 | E8: {=_xlfn.LET( _xlpm.seq, _xlfn.SEQUENCE(COUNTA('Elo calculation'!$A:$A)/4, 1, 2, 4), _xlpm.dates, INDEX('Elo calculation'!$C:$C, _xlpm.seq), _xlpm.limite, EOMONTH(D$1,0), _xlpm.ligdate, MAX(IF(_xlpm.dates <= _xlpm.limite, _xlpm.seq, 0)), _xlpm.coljoueur, MATCH($A8, 'Elo calculation'!$1:$1, 0), INDEX('Elo calculation'!$A:$ZZ, _xlpm.ligdate + 4, _xlpm.coljoueur) )} -> 1084.9305 | F8: {=_xlfn.LET( _xlpm.vals, _xlfn._xlws.FILTER(E:E, (D:D>0)*(ISNUMBER(E:E)), ""), _xlpm.nPlus, SUM(--(_xlpm.vals > E8)), _xlpm.nEgal, SUM(--(_xlpm.vals = E8)), _xlpm.res, 1 + _xlpm.nPlus + (_xlpm.nEgal - 1) / 2, IF(D8=0, "", _xlpm.res) )} -> 6 | G8: {=_xlfn.LET( _xlpm.ming, Constantes!$B$8, _xlpm.maxmma, Constantes!$B$6, _xlpm.minmma, Constantes!$B$7, _xlpm.maxp, MAX(_xlfn._xlws.FILTER(F:F, ISNUMBER(F:F))), _xlpm.place, IF(F8="", _xlpm.maxp, F8), MIN(_xlpm.ming,D8)/_xlpm.ming * ((_xlpm.maxp - _xlpm.place) / (_xlpm.maxp - 1) * (_xlpm.maxmma - _xlpm.minmma) + _xlpm.minmma) )} -> 410 | H8: =C8+G8 -> 410 | I8: {=_xlfn.LET( _xlpm.dates, INDEX('Elo calculation'!$C:$C, _xlfn.SEQUENCE(COUNTA('Elo calculation'!$C:$C)-2,1,2,4)), _xlpm.pts, INDEX('Elo calculation'!$A:$ZZ, _xlfn.SEQUENCE(COUNTA('Elo calculation'!$C:$C)-2,1,3,4), MATCH($A8,'Elo calculation'!$1:$1,0)), _xlpm.nbparties, SUMPRODUCT(--(_xlpm.dates <= EOMONTH(I$1,0)), --(_xlpm.dates >= I$1), --(_xlpm.pts <> "")), _xlpm.nbparties )} -> 9 | J8: {=_xlfn.LET( _xlpm.seq, _xlfn.SEQUENCE(COUNTA('Elo calculation'!$A:$A)/4, 1, 2, 4), _xlpm.dates, INDEX('Elo calculation'!$C:$C, _xlpm.seq), _xlpm.limite, EOMONTH(I$1,0), _xlpm.ligdate, MAX(IF(_xlpm.dates <= _xlpm.limite, _xlpm.seq, 0)), _xlpm.coljoueur, MATCH($A8, 'Elo calculation'!$1:$1, 0), INDEX('Elo calculation'!$A:$ZZ, _xlpm.ligdate + 4, _xlpm.coljoueur) )} -> 912.81564 | K8: {=_xlfn.LET( _xlpm.vals, _xlfn._xlws.FILTER(J:J, (I:I>0)*(ISNUMBER(J:J)), ""), _xlpm.nPlus, SUM(--(_xlpm.vals > J8)), _xlpm.nEgal, SUM(--(_xlpm.vals = J8)), _xlpm.res, 1 + _xlpm.nPlus + (_xlpm.nEgal - 1) / 2, IF(I8=0, "", _xlpm.res) )} -> 27 | L8: {=_xlfn.LET( _xlpm.ming, Constantes!$B$8, _xlpm.maxmma, Constantes!$B$6, _xlpm.minmma, Constantes!$B$7, _xlpm.maxp, MAX(_xlfn._xlws.FILTER(K:K, ISNUMBER(K:K))), _xlpm.place, IF(K8="", _xlpm.maxp, K8), MIN(_xlpm.ming,I8)/_xlpm.ming * ((_xlpm.maxp - _xlpm.place) / (_xlpm.maxp - 1) * (_xlpm.maxmma - _xlpm.minmma) + _xlpm.minmma) )} -> 155.88235 | M8: =H8+L8 -> 565.88235 | N8: {=_xlfn.LET( _xlpm.dates, INDEX('Elo calculation'!$C:$C, _xlfn.SEQUENCE(COUNTA('Elo calculation'!$C:$C)-2,1,2,4)), _xlpm.pts, INDEX('Elo calculation'!$A:$ZZ, _xlfn.SEQUENCE(COUNTA('Elo calculation'!$C:$C)-2,1,3,4), MATCH($A8,'Elo calculation'!$1:$1,0)), _xlpm.nbparties, SUMPRODUCT(--(_xlpm.dates <= EOMONTH(N$1,0)), --(_xlpm.dates >= N$1), --(_xlpm.pts <> "")), _xlpm.nbparties )} -> 3 | O8: {=_xlfn.LET( _xlpm.seq, _xlfn.SEQUENCE(COUNTA('Elo calculation'!$A:$A)/4, 1, 2, 4), _xlpm.dates, INDEX('Elo calculation'!$C:$C, _xlpm.seq), _xlpm.limite, EOMONTH(N$1,0), _xlpm.ligdate, MAX(IF(_xlpm.dates <= _xlpm.limite, _xlpm.seq, 0)), _xlpm.coljoueur, MATCH($A8, 'Elo calculation'!$1:$1, 0), INDEX('Elo calculation'!$A:$ZZ, _xlpm.ligdate + 4, _xlpm.coljoueur) )} -> 883.37235 | P8: {=_xlfn.LET( _xlpm.vals, _xlfn._xlws.FILTER(O:O, (N:N>0)*(ISNUMBER(O:O)), ""), _xlpm.nPlus, SUM(--(_xlpm.vals > O8)), _xlpm.nEgal, SUM(--(_xlpm.vals = O8)), _xlpm.res, 1 + _xlpm.nPlus + (_xlpm.nEgal - 1) / 2, IF(N8=0, "", _xlpm.res) )} -> 21 | Q8: {=_xlfn.LET( _xlpm.ming, Constantes!$B$8, _xlpm.maxmma, Constantes!$B$6, _xlpm.minmma, Constantes!$B$7, _xlpm.maxp, MAX(_xlfn._xlws.FILTER(P:P, ISNUMBER(P:P))), _xlpm.place, IF(P8="", _xlpm.maxp, P8), MIN(_xlpm.ming,N8)/_xlpm.ming * ((_xlpm.maxp - _xlpm.place) / (_xlpm.maxp - 1) * (_xlpm.maxmma - _xlpm.minmma) + _xlpm.minmma) )} -> 81.521739 | R8: =M8+Q8 -> 647.40409
A9: Mathieu | B9: 1030.135 | C9: 0 | D9: {=_xlfn.LET( _xlpm.dates, INDEX('Elo calculation'!$C:$C, _xlfn.SEQUENCE(COUNTA('Elo calculation'!$C:$C)-2,1,2,4)), _xlpm.pts, INDEX('Elo calculation'!$A:$ZZ, _xlfn.SEQUENCE(COUNTA('Elo calculation'!$C:$C)-2,1,3,4), MATCH($A9,'Elo calculation'!$1:$1,0)), _xlpm.nbparties, SUMPRODUCT(--(_xlpm.dates <= EOMONTH(D$1,0)), --(_xlpm.dates >= D$1), --(_xlpm.pts <> "")), _xlpm.nbparties )} -> 2 | E9: {=_xlfn.LET( _xlpm.seq, _xlfn.SEQUENCE(COUNTA('Elo calculation'!$A:$A)/4, 1, 2, 4), _xlpm.dates, INDEX('Elo calculation'!$C:$C, _xlpm.seq), _xlpm.limite, EOMONTH(D$1,0), _xlpm.ligdate, MAX(IF(_xlpm.dates <= _xlpm.limite, _xlpm.seq, 0)), _xlpm.coljoueur, MATCH($A9, 'Elo calculation'!$1:$1, 0), INDEX('Elo calculation'!$A:$ZZ, _xlpm.ligdate + 4, _xlpm.coljoueur) )} -> 938.49434 | F9: {=_xlfn.LET( _xlpm.vals, _xlfn._xlws.FILTER(E:E, (D:D>0)*(ISNUMBER(E:E)), ""), _xlpm.nPlus, SUM(--(_xlpm.vals > E9)), _xlpm.nEgal, SUM(--(_xlpm.vals = E9)), _xlpm.res, 1 + _xlpm.nPlus + (_xlpm.nEgal - 1) / 2, IF(D9=0, "", _xlpm.res) )} -> 18 | G9: {=_xlfn.LET( _xlpm.ming, Constantes!$B$8, _xlpm.maxmma, Constantes!$B$6, _xlpm.minmma, Constantes!$B$7, _xlpm.maxp, MAX(_xlfn._xlws.FILTER(F:F, ISNUMBER(F:F))), _xlpm.place, IF(F9="", _xlpm.maxp, F9), MIN(_xlpm.ming,D9)/_xlpm.ming * ((_xlpm.maxp - _xlpm.place) / (_xlpm.maxp - 1) * (_xlpm.maxmma - _xlpm.minmma) + _xlpm.minmma) )} -> 97 | H9: =C9+G9 -> 97 | I9: {=_xlfn.LET( _xlpm.dates, INDEX('Elo calculation'!$C:$C, _xlfn.SEQUENCE(COUNTA('Elo calculation'!$C:$C)-2,1,2,4)), _xlpm.pts, INDEX('Elo calculation'!$A:$ZZ, _xlfn.SEQUENCE(COUNTA('Elo calculation'!$C:$C)-2,1,3,4), MATCH($A9,'Elo calculation'!$1:$1,0)), _xlpm.nbparties, SUMPRODUCT(--(_xlpm.dates <= EOMONTH(I$1,0)), --(_xlpm.dates >= I$1), --(_xlpm.pts <> "")), _xlpm.nbparties )} -> 6 | J9: {=_xlfn.LET( _xlpm.seq, _xlfn.SEQUENCE(COUNTA('Elo calculation'!$A:$A)/4, 1, 2, 4), _xlpm.dates, INDEX('Elo calculation'!$C:$C, _xlpm.seq), _xlpm.limite, EOMONTH(I$1,0), _xlpm.ligdate, MAX(IF(_xlpm.dates <= _xlpm.limite, _xlpm.seq, 0)), _xlpm.coljoueur, MATCH($A9, 'Elo calculation'!$1:$1, 0), INDEX('Elo calculation'!$A:$ZZ, _xlpm.ligdate + 4, _xlpm.coljoueur) )} -> 1032.4323 | K9: {=_xlfn.LET( _xlpm.vals, _xlfn._xlws.FILTER(J:J, (I:I>0)*(ISNUMBER(J:J)), ""), _xlpm.nPlus, SUM(--(_xlpm.vals > J9)), _xlpm.nEgal, SUM(--(_xlpm.vals = J9)), _xlpm.res, 1 + _xlpm.nPlus + (_xlpm.nEgal - 1) / 2, IF(I9=0, "", _xlpm.res) )} -> 12 | L9: {=_xlfn.LET( _xlpm.ming, Constantes!$B$8, _xlpm.maxmma, Constantes!$B$6, _xlpm.minmma, Constantes!$B$7, _xlpm.maxp, MAX(_xlfn._xlws.FILTER(K:K, ISNUMBER(K:K))), _xlpm.place, IF(K9="", _xlpm.maxp, K9), MIN(_xlpm.ming,I9)/_xlpm.ming * ((_xlpm.maxp - _xlpm.place) / (_xlpm.maxp - 1) * (_xlpm.maxmma - _xlpm.minmma) + _xlpm.minmma) )} -> 354.41176 | M9: =H9+L9 -> 451.41176 | N9: {=_xlfn.LET( _xlpm.dates, INDEX('Elo calculation'!$C:$C, _xlfn.SEQUENCE(COUNTA('Elo calculation'!$C:$C)-2,1,2,4)), _xlpm.pts, INDEX('Elo calculation'!$A:$ZZ, _xlfn.SEQUENCE(COUNTA('Elo calculation'!$C:$C)-2,1,3,4), MATCH($A9,'Elo calculation'!$1:$1,0)), _xlpm.nbparties, SUMPRODUCT(--(_xlpm.dates <= EOMONTH(N$1,0)), --(_xlpm.dates >= N$1), --(_xlpm.pts <> "")), _xlpm.nbparties )} -> 5 | O9: {=_xlfn.LET( _xlpm.seq, _xlfn.SEQUENCE(COUNTA('Elo calculation'!$A:$A)/4, 1, 2, 4), _xlpm.dates, INDEX('Elo calculation'!$C:$C, _xlpm.seq), _xlpm.limite, EOMONTH(N$1,0), _xlpm.ligdate, MAX(IF(_xlpm.dates <= _xlpm.limite, _xlpm.seq, 0)), _xlpm.coljoueur, MATCH($A9, 'Elo calculation'!$1:$1, 0), INDEX('Elo calculation'!$A:$ZZ, _xlpm.ligdate + 4, _xlpm.coljoueur) )} -> 977.4838 | P9: {=_xlfn.LET( _xlpm.vals, _xlfn._xlws.FILTER(O:O, (N:N>0)*(ISNUMBER(O:O)), ""), _xlpm.nPlus, SUM(--(_xlpm.vals > O9)), _xlpm.nEgal, SUM(--(_xlpm.vals = O9)), _xlpm.res, 1 + _xlpm.nPlus + (_xlpm.nEgal - 1) / 2, IF(N9=0, "", _xlpm.res) )} -> 13 | Q9: {=_xlfn.LET( _xlpm.ming, Constantes!$B$8, _xlpm.maxmma, Constantes!$B$6, _xlpm.minmma, Constantes!$B$7, _xlpm.maxp, MAX(_xlfn._xlws.FILTER(P:P, ISNUMBER(P:P))), _xlpm.place, IF(P9="", _xlpm.maxp, P9), MIN(_xlpm.ming,N9)/_xlpm.ming * ((_xlpm.maxp - _xlpm.place) / (_xlpm.maxp - 1) * (_xlpm.maxmma - _xlpm.minmma) + _xlpm.minmma) )} -> 265.21739 | R9: =M9+Q9 -> 716.62916
A10: Ghislaine | B10: 923.36 | C10: 0 | D10: {=_xlfn.LET( _xlpm.dates, INDEX('Elo calculation'!$C:$C, _xlfn.SEQUENCE(COUNTA('Elo calculation'!$C:$C)-2,1,2,4)), _xlpm.pts, INDEX('Elo calculation'!$A:$ZZ, _xlfn.SEQUENCE(COUNTA('Elo calculation'!$C:$C)-2,1,3,4), MATCH($A10,'Elo calculation'!$1:$1,0)), _xlpm.nbparties, SUMPRODUCT(--(_xlpm.dates <= EOMONTH(D$1,0)), --(_xlpm.dates >= D$1), --(_xlpm.pts <> "")), _xlpm.nbparties )} -> 4 | E10: {=_xlfn.LET( _xlpm.seq, _xlfn.SEQUENCE(COUNTA('Elo calculation'!$A:$A)/4, 1, 2, 4), _xlpm.dates, INDEX('Elo calculation'!$C:$C, _xlpm.seq), _xlpm.limite, EOMONTH(D$1,0), _xlpm.ligdate, MAX(IF(_xlpm.dates <= _xlpm.limite, _xlpm.seq, 0)), _xlpm.coljoueur, MATCH($A10, 'Elo calculation'!$1:$1, 0), INDEX('Elo calculation'!$A:$ZZ, _xlpm.ligdate + 4, _xlpm.coljoueur) )} -> 907.51653 | F10: {=_xlfn.LET( _xlpm.vals, _xlfn._xlws.FILTER(E:E, (D:D>0)*(ISNUMBER(E:E)), ""), _xlpm.nPlus, SUM(--(_xlpm.vals > E10)), _xlpm.nEgal, SUM(--(_xlpm.vals = E10)), _xlpm.res, 1 + _xlpm.nPlus + (_xlpm.nEgal - 1) / 2, IF(D10=0, "", _xlpm.res) )} -> 21 | G10: {=_xlfn.LET( _xlpm.ming, Constantes!$B$8, _xlpm.maxmma, Constantes!$B$6, _xlpm.minmma, Constantes!$B$7, _xlpm.maxp, MAX(_xlfn._xlws.FILTER(F:F, ISNUMBER(F:F))), _xlpm.place, IF(F10="", _xlpm.maxp, F10), MIN(_xlpm.ming,D10)/_xlpm.ming * ((_xlpm.maxp - _xlpm.place) / (_xlpm.maxp - 1) * (_xlpm.maxmma - _xlpm.minmma) + _xlpm.minmma) )} -> 140 | H10: =C10+G10 -> 140 | I10: {=_xlfn.LET( _xlpm.dates, INDEX('Elo calculation'!$C:$C, _xlfn.SEQUENCE(COUNTA('Elo calculation'!$C:$C)-2,1,2,4)), _xlpm.pts, INDEX('Elo calculation'!$A:$ZZ, _xlfn.SEQUENCE(COUNTA('Elo calculation'!$C:$C)-2,1,3,4), MATCH($A10,'Elo calculation'!$1:$1,0)), _xlpm.nbparties, SUMPRODUCT(--(_xlpm.dates <= EOMONTH(I$1,0)), --(_xlpm.dates >= I$1), --(_xlpm.pts <> "")), _xlpm.nbparties )} -> 6 | J10: {=_xlfn.LET( _xlpm.seq, _xlfn.SEQUENCE(COUNTA('Elo calculation'!$A:$A)/4, 1, 2, 4), _xlpm.dates, INDEX('Elo calculation'!$C:$C, _xlpm.seq), _xlpm.limite, EOMONTH(I$1,0), _xlpm.ligdate, MAX(IF(_xlpm.dates <= _xlpm.limite, _xlpm.seq, 0)), _xlpm.coljoueur, MATCH($A10, 'Elo calculation'!$1:$1, 0), INDEX('Elo calculation'!$A:$ZZ, _xlpm.ligdate + 4, _xlpm.coljoueur) )} -> 1076.8547 | K10: {=_xlfn.LET( _xlpm.vals, _xlfn._xlws.FILTER(J:J, (I:I>0)*(ISNUMBER(J:J)), ""), _xlpm.nPlus, SUM(--(_xlpm.vals > J10)), _xlpm.nEgal, SUM(--(_xlpm.vals = J10)), _xlpm.res, 1 + _xlpm.nPlus + (_xlpm.nEgal - 1) / 2, IF(I10=0, "", _xlpm.res) )} -> 7 | L10: {=_xlfn.LET( _xlpm.ming, Constantes!$B$8, _xlpm.maxmma, Constantes!$B$6, _xlpm.minmma, Constantes!$B$7, _xlpm.maxp, MAX(_xlfn._xlws.FILTER(K:K, ISNUMBER(K:K))), _xlpm.place, IF(K10="", _xlpm.maxp, K10), MIN(_xlpm.ming,I10)/_xlpm.ming * ((_xlpm.maxp - _xlpm.place) / (_xlpm.maxp - 1) * (_xlpm.maxmma - _xlpm.minmma) + _xlpm.minmma) )} -> 420.58824 | M10: =H10+L10 -> 560.58824 | N10: {=_xlfn.LET( _xlpm.dates, INDEX('Elo calculation'!$C:$C, _xlfn.SEQUENCE(COUNTA('Elo calculation'!$C:$C)-2,1,2,4)), _xlpm.pts, INDEX('Elo calculation'!$A:$ZZ, _xlfn.SEQUENCE(COUNTA('Elo calculation'!$C:$C)-2,1,3,4), MATCH($A10,'Elo calculation'!$1:$1,0)), _xlpm.nbparties, SUMPRODUCT(--(_xlpm.dates <= EOMONTH(N$1,0)), --(_xlpm.dates >= N$1), --(_xlpm.pts <> "")), _xlpm.nbparties )} -> 2 | O10: {=_xlfn.LET( _xlpm.seq, _xlfn.SEQUENCE(COUNTA('Elo calculation'!$A:$A)/4, 1, 2, 4), _xlpm.dates, INDEX('Elo calculation'!$C:$C, _xlpm.seq), _xlpm.limite, EOMONTH(N$1,0), _xlpm.ligdate, MAX(IF(_xlpm.dates <= _xlpm.limite, _xlpm.seq, 0)), _xlpm.coljoueur, MATCH($A10, 'Elo calculation'!$1:$1, 0), INDEX('Elo calculation'!$A:$ZZ, _xlpm.ligdate + 4, _xlpm.coljoueur) )} -> 1062.2548 | P10: {=_xlfn.LET( _xlpm.vals, _xlfn._xlws.FILTER(O:O, (N:N>0)*(ISNUMBER(O:O)), ""), _xlpm.nPlus, SUM(--(_xlpm.vals > O10)), _xlpm.nEgal, SUM(--(_xlpm.vals = O10)), _xlpm.res, 1 + _xlpm.nPlus + (_xlpm.nEgal - 1) / 2, IF(N10=0, "", _xlpm.res) )} -> 6 | Q10: {=_xlfn.LET( _xlpm.ming, Constantes!$B$8, _xlpm.maxmma, Constantes!$B$6, _xlpm.minmma, Constantes!$B$7, _xlpm.maxp, MAX(_xlfn._xlws.FILTER(P:P, ISNUMBER(P:P))), _xlpm.place, IF(P10="", _xlpm.maxp, P10), MIN(_xlpm.ming,N10)/_xlpm.ming * ((_xlpm.maxp - _xlpm.place) / (_xlpm.maxp - 1) * (_xlpm.maxmma - _xlpm.minmma) + _xlpm.minmma) )} -> 201.08696 | R10: =M10+Q10 -> 761.67519
A11: Francoise | B11: 1000 | C11: 0 | D11: {=_xlfn.LET( _xlpm.dates, INDEX('Elo calculation'!$C:$C, _xlfn.SEQUENCE(COUNTA('Elo calculation'!$C:$C)-2,1,2,4)), _xlpm.pts, INDEX('Elo calculation'!$A:$ZZ, _xlfn.SEQUENCE(COUNTA('Elo calculation'!$C:$C)-2,1,3,4), MATCH($A11,'Elo calculation'!$1:$1,0)), _xlpm.nbparties, SUMPRODUCT(--(_xlpm.dates <= EOMONTH(D$1,0)), --(_xlpm.dates >= D$1), --(_xlpm.pts <> "")), _xlpm.nbparties )} -> 5 | E11: {=_xlfn.LET( _xlpm.seq, _xlfn.SEQUENCE(COUNTA('Elo calculation'!$A:$A)/4, 1, 2, 4), _xlpm.dates, INDEX('Elo calculation'!$C:$C, _xlpm.seq), _xlpm.limite, EOMONTH(D$1,0), _xlpm.ligdate, MAX(IF(_xlpm.dates <= _xlpm.limite, _xlpm.seq, 0)), _xlpm.coljoueur, MATCH($A11, 'Elo calculation'!$1:$1, 0), INDEX('Elo calculation'!$A:$ZZ, _xlpm.ligdate + 4, _xlpm.coljoueur) )} -> 801.48943 | F11: {=_xlfn.LET( _xlpm.vals, _xlfn._xlws.FILTER(E:E, (D:D>0)*(ISNUMBER(E:E)), ""), _xlpm.nPlus, SUM(--(_xlpm.vals > E11)), _xlpm.nEgal, SUM(--(_xlpm.vals = E11)), _xlpm.res, 1 + _xlpm.nPlus + (_xlpm.nEgal - 1) / 2, IF(D11=0, "", _xlpm.res) )} -> 26 | G11: {=_xlfn.LET( _xlpm.ming, Constantes!$B$8, _xlpm.maxmma, Constantes!$B$6, _xlpm.minmma, Constantes!$B$7, _xlpm.maxp, MAX(_xlfn._xlws.FILTER(F:F, ISNUMBER(F:F))), _xlpm.place, IF(F11="", _xlpm.maxp, F11), MIN(_xlpm.ming,D11)/_xlpm.ming * ((_xlpm.maxp - _xlpm.place) / (_xlpm.maxp - 1) * (_xlpm.maxmma - _xlpm.minmma) + _xlpm.minmma) )} -> 50 | H11: =C11+G11 -> 50 | I11: {=_xlfn.LET( _xlpm.dates, INDEX('Elo calculation'!$C:$C, _xlfn.SEQUENCE(COUNTA('Elo calculation'!$C:$C)-2,1,2,4)), _xlpm.pts, INDEX('Elo calculation'!$A:$ZZ, _xlfn.SEQUENCE(COUNTA('Elo calculation'!$C:$C)-2,1,3,4), MATCH($A11,'Elo calculation'!$1:$1,0)), _xlpm.nbparties, SUMPRODUCT(--(_xlpm.dates <= EOMONTH(I$1,0)), --(_xlpm.dates >= I$1), --(_xlpm.pts <> "")), _xlpm.nbparties )} -> 4 | J11: {=_xlfn.LET( _xlpm.seq, _xlfn.SEQUENCE(COUNTA('Elo calculation'!$A:$A)/4, 1, 2, 4), _xlpm.dates, INDEX('Elo calculation'!$C:$C, _xlpm.seq), _xlpm.limite, EOMONTH(I$1,0), _xlpm.ligdate, MAX(IF(_xlpm.dates <= _xlpm.limite, _xlpm.seq, 0)), _xlpm.coljoueur, MATCH($A11, 'Elo calculation'!$1:$1, 0), INDEX('Elo calculation'!$A:$ZZ, _xlpm.ligdate + 4, _xlpm.coljoueur) )} -> 783.12422 | K11: {=_xlfn.LET( _xlpm.vals, _xlfn._xlws.FILTER(J:J, (I:I>0)*(ISNUMBER(J:J)), ""), _xlpm.nPlus, SUM(--(_xlpm.vals > J11)), _xlpm.nEgal, SUM(--(_xlpm.vals = J11)), _xlpm.res, 1 + _xlpm.nPlus + (_xlpm.nEgal - 1) / 2, IF(I11=0, "", _xlpm.res) )} -> 35 | L11: {=_xlfn.LET( _xlpm.ming, Constantes!$B$8, _xlpm.maxmma, Constantes!$B$6, _xlpm.minmma, Constantes!$B$7, _xlpm.maxp, MAX(_xlfn._xlws.FILTER(K:K, ISNUMBER(K:K))), _xlpm.place, IF(K11="", _xlpm.maxp, K11), MIN(_xlpm.ming,I11)/_xlpm.ming * ((_xlpm.maxp - _xlpm.place) / (_xlpm.maxp - 1) * (_xlpm.maxmma - _xlpm.minmma) + _xlpm.minmma) )} -> 50 | M11: =H11+L11 -> 100 | N11: {=_xlfn.LET( _xlpm.dates, INDEX('Elo calculation'!$C:$C, _xlfn.SEQUENCE(COUNTA('Elo calculation'!$C:$C)-2,1,2,4)), _xlpm.pts, INDEX('Elo calculation'!$A:$ZZ, _xlfn.SEQUENCE(COUNTA('Elo calculation'!$C:$C)-2,1,3,4), MATCH($A11,'Elo calculation'!$1:$1,0)), _xlpm.nbparties, SUMPRODUCT(--(_xlpm.dates <= EOMONTH(N$1,0)), --(_xlpm.dates >= N$1), --(_xlpm.pts <> "")), _xlpm.nbparties )} -> 2 | O11: {=_xlfn.LET( _xlpm.seq, _xlfn.SEQUENCE(COUNTA('Elo calculation'!$A:$A)/4, 1, 2, 4), _xlpm.dates, INDEX('Elo calculation'!$C:$C, _xlpm.seq), _xlpm.limite, EOMONTH(N$1,0), _xlpm.ligdate, MAX(IF(_xlpm.dates <= _xlpm.limite, _xlpm.seq, 0)), _xlpm.coljoueur, MATCH($A11, 'Elo calculation'!$1:$1, 0), INDEX('Elo calculation'!$A:$ZZ, _xlpm.ligdate + 4, _xlpm.coljoueur) )} -> 775.39796 | P11: {=_xlfn.LET( _xlpm.vals, _xlfn._xlws.FILTER(O:O, (N:N>0)*(ISNUMBER(O:O)), ""), _xlpm.nPlus, SUM(--(_xlpm.vals > O11)), _xlpm.nEgal, SUM(--(_xlpm.vals = O11)), _xlpm.res, 1 + _xlpm.nPlus + (_xlpm.nEgal - 1) / 2, IF(N11=0, "", _xlpm.res) )} -> 24 | Q11: {=_xlfn.LET( _xlpm.ming, Constantes!$B$8, _xlpm.maxmma, Constantes!$B$6, _xlpm.minmma, Constantes!$B$7, _xlpm.maxp, MAX(_xlfn._xlws.FILTER(P:P, ISNUMBER(P:P))), _xlpm.place, IF(P11="", _xlpm.maxp, P11), MIN(_xlpm.ming,N11)/_xlpm.ming * ((_xlpm.maxp - _xlpm.place) / (_xlpm.maxp - 1) * (_xlpm.maxmma - _xlpm.minmma) + _xlpm.minmma) )} -> 25 | R11: =M11+Q11 -> 125
A12: Beatrice | B12: 1000 | C12: 0 | D12: {=_xlfn.LET( _xlpm.dates, INDEX('Elo calculation'!$C:$C, _xlfn.SEQUENCE(COUNTA('Elo calculation'!$C:$C)-2,1,2,4)), _xlpm.pts, INDEX('Elo calculation'!$A:$ZZ, _xlfn.SEQUENCE(COUNTA('Elo calculation'!$C:$C)-2,1,3,4), MATCH($A12,'Elo calculation'!$1:$1,0)), _xlpm.nbparties, SUMPRODUCT(--(_xlpm.dates <= EOMONTH(D$1,0)), --(_xlpm.dates >= D$1), --(_xlpm.pts <> "")), _xlpm.nbparties )} -> 2 | E12: {=_xlfn.LET( _xlpm.seq, _xlfn.SEQUENCE(COUNTA('Elo calculation'!$A:$A)/4, 1, 2, 4), _xlpm.dates, INDEX('Elo calculation'!$C:$C, _xlpm.seq), _xlpm.limite, EOMONTH(D$1,0), _xlpm.ligdate, MAX(IF(_xlpm.dates <= _xlpm.limite, _xlpm.seq, 0)), _xlpm.coljoueur, MATCH($A12, 'Elo calculation'!$1:$1, 0), INDEX('Elo calculation'!$A:$ZZ, _xlpm.ligdate + 4, _xlpm.coljoueur) )} -> 913.41986 | F12: {=_xlfn.LET( _xlpm.vals, _xlfn._xlws.FILTER(E:E, (D:D>0)*(ISNUMBER(E:E)), ""), _xlpm.nPlus, SUM(--(_xlpm.vals > E12)), _xlpm.nEgal, SUM(--(_xlpm.vals = E12)), _xlpm.res, 1 + _xlpm.nPlus + (_xlpm.nEgal - 1) / 2, IF(D12=0, "", _xlpm.res) )} -> 20 | G12: {=_xlfn.LET( _xlpm.ming, Constantes!$B$8, _xlpm.maxmma, Constantes!$B$6, _xlpm.minmma, Constantes!$B$7, _xlpm.maxp, MAX(_xlfn._xlws.FILTER(F:F, ISNUMBER(F:F))), _xlpm.place, IF(F12="", _xlpm.maxp, F12), MIN(_xlpm.ming,D12)/_xlpm.ming * ((_xlpm.maxp - _xlpm.place) / (_xlpm.maxp - 1) * (_xlpm.maxmma - _xlpm.minmma) + _xlpm.minmma) )} -> 79 | H12: =C12+G12 -> 79 | I12: {=_xlfn.LET( _xlpm.dates, INDEX('Elo calculation'!$C:$C, _xlfn.SEQUENCE(COUNTA('Elo calculation'!$C:$C)-2,1,2,4)), _xlpm.pts, INDEX('Elo calculation'!$A:$ZZ, _xlfn.SEQUENCE(COUNTA('Elo calculation'!$C:$C)-2,1,3,4), MATCH($A12,'Elo calculation'!$1:$1,0)), _xlpm.nbparties, SUMPRODUCT(--(_xlpm.dates <= EOMONTH(I$1,0)), --(_xlpm.dates >= I$1), --(_xlpm.pts <> "")), _xlpm.nbparties )} -> 1 | J12: {=_xlfn.LET( _xlpm.seq, _xlfn.SEQUENCE(COUNTA('Elo calculation'!$A:$A)/4, 1, 2, 4), _xlpm.dates, INDEX('Elo calculation'!$C:$C, _xlpm.seq), _xlpm.limite, EOMONTH(I$1,0), _xlpm.ligdate, MAX(IF(_xlpm.dates <= _xlpm.limite, _xlpm.seq, 0)), _xlpm.coljoueur, MATCH($A12, 'Elo calculation'!$1:$1, 0), INDEX('Elo calculation'!$A:$ZZ, _xlpm.ligdate + 4, _xlpm.coljoueur) )} -> 874.31052 | K12: {=_xlfn.LET( _xlpm.vals, _xlfn._xlws.FILTER(J:J, (I:I>0)*(ISNUMBER(J:J)), ""), _xlpm.nPlus, SUM(--(_xlpm.vals > J12)), _xlpm.nEgal, SUM(--(_xlpm.vals = J12)), _xlpm.res, 1 + _xlpm.nPlus + (_xlpm.nEgal - 1) / 2, IF(I12=0, "", _xlpm.res) )} -> 33 | L12: {=_xlfn.LET( _xlpm.ming, Constantes!$B$8, _xlpm.maxmma, Constantes!$B$6, _xlpm.minmma, Constantes!$B$7, _xlpm.maxp, MAX(_xlfn._xlws.FILTER(K:K, ISNUMBER(K:K))), _xlpm.place, IF(K12="", _xlpm.maxp, K12), MIN(_xlpm.ming,I12)/_xlpm.ming * ((_xlpm.maxp - _xlpm.place) / (_xlpm.maxp - 1) * (_xlpm.maxmma - _xlpm.minmma) + _xlpm.minmma) )} -> 19.117647 | M12: =H12+L12 -> 98.117647 | N12: {=_xlfn.LET( _xlpm.dates, INDEX('Elo calculation'!$C:$C, _xlfn.SEQUENCE(COUNTA('Elo calculation'!$C:$C)-2,1,2,4)), _xlpm.pts, INDEX('Elo calculation'!$A:$ZZ, _xlfn.SEQUENCE(COUNTA('Elo calculation'!$C:$C)-2,1,3,4), MATCH($A12,'Elo calculation'!$1:$1,0)), _xlpm.nbparties, SUMPRODUCT(--(_xlpm.dates <= EOMONTH(N$1,0)), --(_xlpm.dates >= N$1), --(_xlpm.pts <> "")), _xlpm.nbparties )} -> 2 | O12: {=_xlfn.LET( _xlpm.seq, _xlfn.SEQUENCE(COUNTA('Elo calculation'!$A:$A)/4, 1, 2, 4), _xlpm.dates, INDEX('Elo calculation'!$C:$C, _xlpm.seq), _xlpm.limite, EOMONTH(N$1,0), _xlpm.ligdate, MAX(IF(_xlpm.dates <= _xlpm.limite, _xlpm.seq, 0)), _xlpm.coljoueur, MATCH($A12, 'Elo calculation'!$1:$1, 0), INDEX('Elo calculation'!$A:$ZZ, _xlpm.ligdate + 4, _xlpm.coljoueur) )} -> 927.45815 | P12: {=_xlfn.LET( _xlpm.vals, _xlfn._xlws.FILTER(O:O, (N:N>0)*(ISNUMBER(O:O)), ""), _xlpm.nPlus, SUM(--(_xlpm.vals > O12)), _xlpm.nEgal, SUM(--(_xlpm.vals = O12)), _xlpm.res, 1 + _xlpm.nPlus + (_xlpm.nEgal - 1) / 2, IF(N12=0, "", _xlpm.res) )} -> 18 | Q12: {=_xlfn.LET( _xlpm.ming, Constantes!$B$8, _xlpm.maxmma, Constantes!$B$6, _xlpm.minmma, Constantes!$B$7, _xlpm.maxp, MAX(_xlfn._xlws.FILTER(P:P, ISNUMBER(P:P))), _xlpm.place, IF(P12="", _xlpm.maxp, P12), MIN(_xlpm.ming,N12)/_xlpm.ming * ((_xlpm.maxp - _xlpm.place) / (_xlpm.maxp - 1) * (_xlpm.maxmma - _xlpm.minmma) + _xlpm.minmma) )} -> 83.695652 | R12: =M12+Q12 -> 181.8133
